Workbook

Sheet Funnel Italia
A1: Great Remigration Plan · Italia · Funnel della popolazione
A2: Albero additivo: ogni voce è la somma delle voci sotto (“+”); “=” marca i totali; le voci “residuo” chiudono la somma per differenza.
A4: Fase 1 | B4: Irregolari: rimpatriabili con la legge attuale
A5: Fase 2 | B5: Regolari extra-UE: entrano quando perdono il titolo (legge ordinaria, accordi di riammissione)
A6: Fase 3 | B6: Cittadini di origine straniera: serve riforma della cittadinanza e un cambio costituzionale/CEDU
A7: Fase 4 | B7: Cittadini UE e protezione temporanea: dipende dal diritto UE
A8: FUORI | B8: Nessuna remigrazione
A10: Codice | B10: Categoria | D10: Persone | E10: % tot. | F10: Fase | G10: Tab di dettaglio | H10: Fonte · anno | I10: Nota
B11: PRESENTI IN ITALIA (residenti + irregolari stimati) | C11: = | D11: =D12+D19+D22+D34 -> 59281939 | E11: =D11/$D$11 -> 1 | H11: Calcolo
A12: A | B12: Cittadini italiani | C12: = | D12: 53572213 | E12: =D12/$D$11 -> 0.90368524 | H12: Eurostat migr_pop1ctz · 1.1.2025
A13: A1 | B13: Nati in Italia | C13: = | D13: =D12-D16 -> 51213465 | E13: =D13/$D$11 -> 0.86389659 | H13: Calcolo: A − A2
A14: A1a | B14: da genitori nati in Italia (residuo) | C14: + | D14: =D13-D15 -> 50057465 | E14: =D14/$D$11 -> 0.84439655 | F14: FUORI | H14: Calcolo: A1 − A1b
A15: A1b | B15: seconda generazione: almeno un genitore nato all’estero | C15: + | D15: 1156000 | E15: =D15/$D$11 -> 0.019500037 | F15: Fase 3 | G15: Seconda generazione | H15: Eurostat LFS 2025, stima | I15: Solo 15-74 anni
A16: A2 | B16: Nati all’estero | C16: = | D16: =D17+D18 -> 2358748 | E16: =D16/$D$11 -> 0.039788645 | G16: Naturalizzati | H16: Eurostat migr_pop5ctz · 1.1.2025 (2.358.748)
A17: A2a | B17: italiani per acquisizione della cittadinanza | C17: + | D17: 2090000 | E17: =D17/$D$11 -> 0.035255257 | F17: Fase 3 | G17: Naturalizzati | H17: ISTAT stima · 31.12.2024 | I17: Include naturalizzati nati in Italia (sovrapposto in parte ad A1b)
A18: A2b | B18: italiani dalla nascita nati all’estero (residuo) | C18: + | D18: =2358748-D17 -> 268748 | E18: =D18/$D$11 -> 0.0045333875 | F18: FUORI | H18: Calcolo: 2.358.748 − A2a | I18: Figli di emigrati, iure sanguinis
A19: B | B19: Cittadini di altri Stati UE | C19: = | D19: =D20+D21 -> 1373870 | E19: =D19/$D$11 -> 0.023175187 | G19: Cittadini UE | H19: Eurostat migr_pop1ctz · 1.1.2025 (1.373.870)
A20: B1 | B20: Romania | C20: + | D20: 1053042 | E20: =D20/$D$11 -> 0.017763285 | F20: Fase 4 | G20: Cittadini UE | H20: ISTAT · 1.1.2025
A21: B2 | B21: altri Stati UE (residuo) | C21: + | D21: =1373870-D20 -> 320828 | E21: =D21/$D$11 -> 0.0054119013 | F21: FUORI | G21: Cittadini UE | H21: Calcolo: 1.373.870 − B1
A22: C | B22: Cittadini extra-UE residenti | C22: = | D22: =D23+D33 -> 3996856 | E22: =D22/$D$11 -> 0.067421142 | H22: Eurostat migr_pop1ctz · 1.1.2025 (3.996.856)
A23: C1 | B23: con permesso di soggiorno valido | C23: = | D23: =D24+D25 -> 3810741 | E23: =D23/$D$11 -> 0.064281652 | H23: ISTAT · 31.12.2024 (3.810.741) | I23: Titoli validi, residenti e non
A24: C1a | B24: lungo soggiornanti (permesso UE senza scadenza) | C24: + | D24: =ROUND(3810741*0.528,0) -> 2012071 | E24: =D24/$D$11 -> 0.033940708 | F24: Fase 2 | G24: Lungo soggiornanti | H24: ISTAT: 52,8% dello stock
A25: C1b | B25: permessi a termine | C25: = | D25: =D26+D32 -> 1798670 | E25: =D25/$D$11 -> 0.030340944 | H25: Calcolo: 3.810.741 − C1a
A26: C1b.1 | B26: asilo e protezione | C26: = | D26: =D27+D28+D29+D30+D31 -> 483673 | E26: =D26/$D$11 -> 0.0081588593 | G26: Protezione e asilo | H26: ISTAT · 31.12.2024 (483.673)
A27: C1b.1a | B27: protezione temporanea (Ucraina) | C27: + | D27: 160600 | E27: =D27/$D$11 -> 0.0027090882 | F27: Fase 4 | G27: Protezione e asilo | H27: ISTAT · 31.12.2024 | I27: Scade il 4.3.2028. Eurostat (stock 2026): 60.485
A28: C1b.1b | B28: richiesta asilo in attesa di decisione | C28: + | D28: 151000 | E28: =D28/$D$11 -> 0.0025471502 | F28: Fase 2 | G28: Protezione e asilo | H28: ISTAT · 31.12.2024
A29: C1b.1c | B29: status di rifugiato | C29: + | D29: 59744 | E29: =D29/$D$11 -> 0.0010077943 | F29: Fase 2 | G29: Protezione e asilo | H29: ISTAT · 31.12.2024
A30: C1b.1d | B30: protezione sussidiaria | C30: + | D30: 54771 | E30: =D30/$D$11 -> 0.00092390703 | F30: Fase 2 | G30: Protezione e asilo | H30: ISTAT · 31.12.2024
A31: C1b.1e | B31: protezione speciale e altre (residuo) | C31: + | D31: =483673-D27-D28-D29-D30 -> 57558 | E31: =D31/$D$11 -> 0.00097091966 | F31: Fase 2 | G31: Protezione e asilo | H31: Calcolo: 483.673 − somma sopra
A32: C1b.2 | B32: lavoro, famiglia, studio, altri motivi (residuo) | C32: + | D32: =3810741-D24-D26 -> 1314997 | E32: =D32/$D$11 -> 0.022182085 | F32: Fase 2 | G32: Permessi a termine | H32: Calcolo: 3.810.741 − C1a − C1b.1
A33: C2 | B33: scarto tra residenti anagrafici e titoli validi (residuo) | C33: + | D33: =3996856-D23 -> 186115 | E33: =D33/$D$11 -> 0.0031394891 | H33: Calcolo: 3.996.856 − C1 | I33: Differenza di fonte, non una categoria
A34: D | B34: Irregolari presenti, non residenti (stima) | C34: = | D34: 339000 | E34: =D34/$D$11 -> 0.0057184364 | F34: Fase 1 | G34: Irregolari | H34: ISMU · 1.1.2025
A36: Flussi 2025 nel perimetro operativo (non sono stock: non si sommano al funnel)
B37: Passaggio | D37: Persone | E37: % ordini | F37: Fase | G37: Tab di dettaglio | H37: Fonte · anno | I37: Nota
A38: F1 | B38: Trovati in posizione irregolare | D38: 82505 | E38: =D38/$D$39 -> 3.8743837 | F38: Fase 1 | G38: Irregolari | H38: Eurostat migr_eipre · 2025
A39: F2 | B39: Ordini di lasciare il territorio | D39: 21295 | E39: =D39/$D$39 -> 1 | F39: Fase 1 | G39: Irregolari | H39: Eurostat migr_eiord · 2025
A40: F3 | B40: Rimpatri verso paesi terzi eseguiti | D40: =D41+D42 -> 4780 | E40: =D40/$D$39 -> 0.22446584 | F40: Fase 1 | G40: Irregolari | H40: Eurostat migr_eirtn · 2025 (4.780) | I40: Tasso di esecuzione 22,4%
A41: F3a | B41: di cui dopo trattenimento in CPR | D41: 1732 | E41: =D41/$D$39 -> 0.081333646 | F41: Fase 1 | G41: Irregolari | H41: ActionAid/UniBa · 2025 | I41: 148 giorni e 16.560 € per rimpatrio
A42: F3b | B42: di cui senza CPR (residuo) | D42: =4780-D41 -> 3048 | E42: =D42/$D$39 -> 0.14313219 | F42: Fase 1 | G42: Irregolari | H42: Calcolo
A43: F4 | B43: Rimpatri volontari assistiti (RVA) | D43: 717 | E43: =D43/$D$39 -> 0.033669876 | F43: Fase 1 | G43: Irregolari | H43: ActionAid/UniBa · gen 2023-lug 2025 | I43: ≈ 300 l’anno
...

Sheet Fase 1
A1: Fase 1 · Irregolari e condannati
A2: Rimpatriabili con la legge attuale. Il problema è l’esecuzione, non la norma.
A4: Codice | B4: Voce | D4: Persone | E4: Fase | F4: Stato giuridico oggi | G4: Cosa si può fare oggi | H4: Cambio di legge per remigrare | I4: Fonte
A5: TOT | B5: Fase 1: persone nel perimetro operativo | C5: = | D5: =D6 -> 339000 | E5: Fase 1 | I5: Funnel Italia
A6: A | B6: Irregolari presenti (stima) | C6: = | D6: ='Funnel Italia'!D34 -> 339000 | E6: Fase 1 | F6: Espellibili (TU art. 13) | G6: Ordine → partenza volontaria 7-30 gg o accompagnamento; CPR fino a 18 mesi (24+6 dal 16.10.2026) | H6: Nessuno. Servono accordi di riammissione (Marocco, Algeria, Pakistan, Bangladesh), canale volontario, identificazione | I6: ISMU · 1.1.2025
A7: A1 | B7: di cui per cittadinanza | C7: + | D7: n.d. | E7: Fase 1 | I7: Eurostat migr_eiord per nazionalità: da estrarre
A8: T | B8: Trasversale: detenuti stranieri (dentro A, Fase 2 e Fase 4) | C8: = | D8: =D9+D10 -> 19816 | E8: Fase 1 | F8: Espulsione come misura di sicurezza (c.p. 235; TU art. 15) o sostitutiva/alternativa (art. 16) | G8: Identificare in carcere; lasciapassare pronto al fine pena; charter | H8: Nessuno: nel 2018 solo 825 espulsioni ex art. 16. Serve riammissione | I8: Min. Giustizia · 30.6.2025
A9: T1 | B9: cittadini UE | C9: + | D9: 2819 | E9: Fase 1 | F9: Dir. 2004/38 artt. 27-28 | G9: Allontanamento art. 20 D.Lgs. 30/2007; esecuzione pena in patria (DQ 2008/909) | H9: Nessuno | I9: Min. Giustizia
A10: T2 | B10: extra-UE | C10: = | D10: =D11+D12+D13 -> 16997 | E10: Fase 1 | I10: Calcolo
A11: T2a | B11: Marocco | C11: + | D11: 4358 | E11: Fase 1 | F11: Idem | G11: Accordo di riammissione da negoziare (visti art. 25a) | H11: Nessuno | I11: Min. Giustizia
A12: T2b | B12: Tunisia | C12: + | D12: 2186 | E12: Fase 1 | F12: Idem | G12: Tetto 80 rimpatri/settimana da alzare | H12: Nessuno | I12: Min. Giustizia
A13: T2c | B13: altre cittadinanze (residuo) | C13: + | D13: =19816-D9-D11-D12 -> 10453 | E13: Fase 1 | F13: Idem | G13: Albania ≈ 1.960, Nigeria ≈ 1.000, Egitto, Senegal, Algeria 400-600 | H13: Nessuno | I13: Calcolo
A14: T3 | B14: Stranieri in esecuzione penale esterna | D14: 29000 | E14: Fase 1 | F14: Misure alternative | G14: Espulsione alternativa (art. 16 c. 5) se residuo ≤ 2 anni | H14: Nessuno | I14: Antigone, 20,4% di 142.773
A16: Flussi 2025 (collegati al Funnel)
A17: Codice | B17: Voce | D17: Persone | E17: Fase | F17: Stato giuridico oggi | G17: Cosa si può fare oggi | H17: Cambio di legge per remigrare | I17: Fonte
A18: F1 | B18: Trovati in posizione irregolare | D18: ='Funnel Italia'!D38 -> 82505 | E18: Fase 1 | F18: Rilevamento di polizia | G18: Fascicolo e decisione entro 24 ore | H18: Nessuno | I18: Eurostat
A19: F2 | B19: Ordini di lasciare il territorio | D19: ='Funnel Italia'!D39 -> 21295 | E19: Fase 1 | F19: Espulsione prefettizia | G19: Esecuzione: 22,4% oggi → 60% nel 2032 | H19: Nessuno | I19: Eurostat
A20: F3 | B20: Rimpatri eseguiti | C20: = | D20: =D21+D22 -> 4780 | E20: Fase 1 | I20: Eurostat
A21: F3a | B21: dopo CPR | C21: + | D21: ='Funnel Italia'!D41 -> 1732 | E21: Fase 1 | F21: Trattenimento (art. 14) | G21: 148 giorni medi: identificare prima, trattenere meno | H21: Nessuno | I21: ActionAid/UniBa
A22: F3b | B22: senza CPR (residuo) | C22: + | D22: ='Funnel Italia'!D42 -> 3048 | E22: Fase 1 | F22: Accompagnamento diretto | H22: Nessuno | I22: Calcolo
A23: F4 | B23: Rimpatri volontari assistiti | D23: ='Funnel Italia'!D43 -> 717 | E23: Fase 1 | F23: Art. 14-ter | G23: Da ≈ 300 a 6.400 l’anno; incentivo 630-2.450 € (UE dal 1.6.2026) | H23: Nessuno: fondi e organizzazione | I23: ActionAid/UniBa
A24: F5 | B24: Dinieghi di asilo in prima istanza (entrano in Fase 1) | D24: 50380 | E24: Fase 1 | F24: Diniego → ricorso → ordine | G24: Atto unico diniego + ordine (Patto UE 2026) | H24: Nessuno | I24: ISTAT 2024: 64,1% di 78.565
A25: O | B25: Riammissione 2025: Tunisia 600 (tetto 80/settimana) · Egitto 454 (18 charter) · Albania e Georgia funzionano · Marocco, Algeria, Pakistan, Bangladesh bloccati | I25: ActionAid/UniBa
A27: Fonti: ISMU 31° Rapporto · Eurostat 2025 · ActionAid/UniBa “Espulsioni” 2026 · Ministero della Giustizia 30.6.2025 · D.Lgs. 286/1998 artt. 13-16, 19; c.p. 235
A28: Verde = valore collegato al tab Funnel Italia. n.d. = nessuna fonte pubblica.

Sheet Fase 2
A1: Fase 2 · Regolari extra-UE
A2: Entrano nel perimetro quando perdono il titolo. Leve: legge ordinaria e accordi di riammissione.
A4: Codice | B4: Voce | D4: Persone | E4: Fase | F4: Stato giuridico oggi | G4: Cosa si può fare oggi | H4: Cambio di legge per remigrare | I4: Fonte
A5: TOT | B5: Fase 2: extra-UE con titolo di soggiorno (esclusa protezione temporanea) | C5: = | D5: =D6+D10+D12 -> 3650141 | E5: Fase 2 | I5: Funnel Italia
A6: A | B6: Lungo soggiornanti | C6: = | D6: ='Funnel Italia'!D24 -> 2012071 | E6: Fase 2 | F6: Status permanente (dir. 2003/109; TU art. 9) | G6: Espulsione solo per gravi motivi di ordine pubblico (art. 9 c. 10); revoca per assenza 12 mesi UE / 6 anni Italia o frode | H6: Senza reati: modifica dir. 2003/109 (unanimità UE). Oggi solo condizionale | I6: ISTAT: 52,8% di 3.810.741
A7: A1 | B7: di cui per cittadinanza | C7: + | D7: n.d. | E7: Fase 2 | I7: ISTAT: solo quote (Moldova 83%, Serbia 74%, Ecuador 73%)
A8: A2 | B8: di cui con condanna per reati gravi (artt. 380-381 c.p.p.) | C8: + | D8: n.d. | E8: Fase 1 | F8: Revocabile ed espellibile (art. 9 c. 4 e c. 10) | G8: Revoca + espulsione | H8: Nessuno; serve il dato DAP | I8: Non pubblicato
A9: A3 | B9: di cui assenti dall’UE > 12 mesi | C9: + | D9: n.d. | E9: Fase 2 | F9: Status decaduto (art. 9 c. 7) | G9: Revoca d’ufficio con controllo EES/SIS | H9: Nessuno; serve il controllo | I9: Non verificato
A10: B | B10: Permessi a termine: lavoro, famiglia, studio, altro | C10: = | D10: ='Funnel Italia'!D32 -> 1314997 | E10: Fase 2 | F10: Permesso 1-3 anni rinnovabile se restano i requisiti (TU art. 5 c. 5) | G10: Mancato rinnovo per perdita reddito/lavoro (dopo 12 mesi attesa occupazione) o reati ostativi → ordine | H10: Legge ordinaria: attesa occupazione 12→6 mesi (art. 22 c. 11), soglie di reddito, reati ostativi (art. 4 c. 3). Limite art. 8 CEDU | I10: Calcolo da ISTAT
A11: B1 | B11: di cui per motivo (lavoro / famiglia / studio) | C11: + | D11: n.d. | E11: Fase 2 | I11: ISTAT non pubblica lo stock per motivo
A12: C | B12: Asilo e protezione (esclusa temporanea) | C12: = | D12: =D13+D14+D15+D16 -> 323073 | E12: Fase 2 | I12: Funnel Italia
A13: C1 | B13: richiesta asilo in attesa | C13: + | D13: ='Funnel Italia'!D28 -> 151000 | E13: Fase 2 | F13: Soggiorno legittimo fino alla decisione | G13: Procedura di frontiera 12 settimane per paesi < 20% (Patto UE); diniego + ordine in un atto | H13: Nessuno: in vigore dal 12.6.2026 | I13: ISTAT · 31.12.2024
A14: C2 | B14: status di rifugiato | C14: + | D14: ='Funnel Italia'!D29 -> 59744 | E14: Fase 2 | F14: Non-refoulement (Ginevra art. 33; TU art. 19) | G14: Solo revoca/cessazione (D.Lgs. 251/07 artt. 9, 13) | H14: Impossibile: Ginevra e Cost. art. 10 | I14: ISTAT · 31.12.2024
A15: C3 | B15: protezione sussidiaria | C15: + | D15: ='Funnel Italia'!D30 -> 54771 | E15: Fase 2 | F15: Permesso 5 anni | G15: Cessazione se cambia la situazione nel paese (art. 15) | H15: Riesame sistematico alla scadenza: prassi | I15: ISTAT · 31.12.2024
A16: C4 | B16: protezione speciale e altre (residuo) | C16: + | D16: ='Funnel Italia'!D31 -> 57558 | E16: Fase 2 | F16: Permesso 2 anni (TU art. 19) | G16: Non rinnovo se cessano i presupposti | H16: Legge ordinaria: restringere art. 19 c. 1.1; limite art. 8 CEDU | I16: Calcolo
A17: T | B17: Trasversale: stranieri nati in Italia senza cittadinanza (dentro B e C) | C17: = | D17: =D18+D19 -> 870000 | E17: Fase 2 | I17: ISTAT RA 2025, stima
A18: T1 | B18: adulti 15-74 | C18: + | D18: 195000 | E18: Fase 2 | F18: Permesso ordinario | G18: Non rinnovo se perde i requisiti; espulsione per reati | H18: Nessuno; i giudici applicano art. 8 CEDU a chi è nato in Italia | I18: Eurostat LFS 2025
A19: T2 | B19: minori (residuo) | C19: + | D19: =870000-D18 -> 675000 | E19: Fase 2 | F19: Non espellibili (TU art. 19 c. 2); a 18 anni elezione di cittadinanza | G19: Nulla fino a 18 anni | H19: Abrogare art. 4 c. 2 L. 91/92: resterebbero in Fase 2 | I19: Calcolo
A21: Flussi 2024
A22: Codice | B22: Voce | D22: Persone | E22: Fase | F22: Stato giuridico oggi | G22: Cosa si può fare oggi | H22: Cambio di legge per remigrare | I22: Fonte
A23: F | B23: Nuovi permessi rilasciati | C23: = | D23: =D24+D25+D26+D27+D28 -> 290119 | E23: Fase 2 | I23: ISTAT 2024 (290.119)
A24: F1 | B24: famiglia | C24: + | D24: 104700 | E24: Fase 2 | F24: Ricongiungimento (TU art. 29) | G24: Requisiti di reddito e alloggio | H24: Legge ordinaria entro dir. 2003/86 | I24: ISTAT 36,1%
A25: F2 | B25: asilo e protezione | C25: + | D25: 104100 | E25: Fase 2 | I25: ISTAT 35,9%
A26: F3 | B26: lavoro | C26: + | D26: 40451 | E26: Fase 2 | F26: Decreto flussi; stagionale 16.739 | G26: Verifica rientro stagionali (EES) | H26: Nessuno | I26: ISTAT 13,9%
A27: F4 | B27: studio | C27: + | D27: 20130 | E27: Fase 2 | F27: Fino a fine corso + 12 mesi | G27: Rientro a fine corso | H27: Legge ordinaria | I27: ISTAT 6,9%
A28: F5 | B28: altri motivi (residuo) | C28: + | D28: =290119-D24-D25-D26-D27 -> 20738 | E28: Fase 2 | I28: Calcolo
A29: G | B29: Prime domande di asilo | D29: 151120 | E29: Fase 2 | I29: Eurostat 2024
A30: G1 | B30: Prime istanze esaminate: respinte 50.380 (64%) → Fase 1 · accolte 28.185 | D30: 78565 | E30: Fase 2 | I30: ISTAT 2024
A31: O | B31: Prime origini 2024 (nuovi permessi): Bangladesh 28.045 · Marocco 25.776 · Albania 24.430 · Egitto 20.217 · Pakistan 17.217 · India 16.907 · Tunisia 15.016 | I31: ISTAT
A33: Fonti: ISTAT Cittadini non comunitari 2024 · Eurostat LFS 2025, migr_asypenctzm · D.Lgs. 286/1998 artt. 4, 5, 9, 19, 22, 29; D.Lgs. 251/2007; Reg. (UE) 2024/1348
A34: Verde = valore collegato al tab Funnel Italia. n.d. = nessuna fonte pubblica.

Sheet Fase 3
A1: Fase 3 · Cittadini italiani di origine straniera
A2: Oggi non esiste alcuno strumento. Serve una riforma costituzionale e l’uscita da vincoli CEDU.
A4: Codice | B4: Voce | D4: Persone | E4: Fase | F4: Stato giuridico oggi | G4: Cosa si può fare oggi | H4: Cambio di legge per remigrare | I4: Fonte
A5: TOT | B5: Fase 3: cittadini di origine straniera | C5: = | D5: =D6+D8 -> 3246000 | E5: Fase 3 | F5: Cittadini a tutti gli effetti (Cost. art. 22; CEDU Prot. 4 art. 3) | G5: Nulla. Solo revoca per terrorismo (L. 91/92 art. 10-bis) e annullamento per frode | H5: Riforma costituzionale artt. 3 e 22 (doppia lettura + referendum) e denuncia del Prot. 4 CEDU; nessun precedente in UE | I5: Funnel Italia
A6: A | B6: Seconda generazione, cittadini 15-74 | C6: = | D6: ='Funnel Italia'!D15 -> 1156000 | E6: Fase 3 | F6: Cittadini dalla nascita o per elezione a 18 anni | G6: Nulla | H6: Come sopra; per i futuri: abrogare l’elezione a 18 anni (art. 4 c. 2) e la trasmissione ai minori (art. 14) → restano in Fase 2 | I6: Eurostat LFS 2025
A7: A1 | B7: di cui per origine del genitore | C7: + | D7: n.d. | E7: Fase 3 | I7: Eurostat non lo pubblica
A8: B | B8: Italiani per acquisizione | C8: = | D8: =D9+D10 -> 2090000 | E8: Fase 3 | F8: Cittadini a tutti gli effetti | G8: Revoca solo per terrorismo entro 3 anni (art. 10-bis) | H8: Revoca estesa ad altri reati: viola Cost. art. 3 (parità) → serve riforma costituzionale; rischio apolidia (Conv. 1961) | I8: ISTAT · 31.12.2024
A9: B1 | B9: di origine extra-UE | C9: + | D9: 1790000 | E9: Fase 3 | F9: Idem | G9: Idem | H9: Idem | I9: ISTAT: 85,6%
A10: B2 | B10: di origine UE (residuo) | C10: + | D10: =2090000-D9 -> 300000 | E10: Fase 3 | F10: Idem | G10: Idem | H10: Idem | I10: Calcolo
A11: T | B11: Trasversale: condannati con cittadinanza italiana di origine straniera | D11: n.d. | E11: Fase 3 | F11: Non espellibili | G11: Revoca solo per terrorismo | H11: Riforma costituzionale | I11: Non pubblicato
A13: Flusso 2024: acquisizioni di cittadinanza (alimentano la Fase 3)
A14: Codice | B14: Voce | D14: Persone | E14: Fase | F14: Stato giuridico oggi | G14: Cosa si può fare oggi | H14: Cambio di legge per remigrare | I14: Fonte
A15: F | B15: Acquisizioni nell’anno | C15: = | D15: =D16+D17+D18+D19+D20+D21 -> 217448 | E15: Fase 3 | I15: ISTAT 2024 (217.448)
A16: F1 | B16: per residenza (10 anni) | C16: + | D16: 85000 | E16: Fase 3 | F16: Concessione discrezionale | G16: Irrigidire requisiti (reddito, lingua B1, reati) | H16: Legge ordinaria: art. 9 | I16: ISTAT, ≈
A17: F2 | B17: minori per trasmissione dai genitori | C17: + | D17: 63000 | E17: Fase 3 | F17: Automatico se conviventi | H17: Legge ordinaria: art. 14 | I17: ISTAT, ≈
A18: F3 | B18: iure sanguinis (avo italiano) | C18: + | D18: 22000 | E18: Fase 3 | F18: Diritto | G18: Già ristretto (D.L. 36/2025) | H18: Legge ordinaria | I18: ISTAT, ≈
A19: F4 | B19: per matrimonio | C19: + | D19: 19000 | E19: Fase 3 | F19: Concessione | G19: Allungare i termini | H19: Legge ordinaria: art. 5 | I19: ISTAT, ≈
A20: F5 | B20: per elezione a 18 anni | C20: + | D20: 11000 | E20: Fase 3 | F20: Diritto | H20: Legge ordinaria: art. 4 c. 2 | I20: ISTAT, ≈
A21: F6 | B21: altre modalità (residuo) | C21: + | D21: =217448-D16-D17-D18-D19-D20 -> 17448 | E21: Fase 3 | I21: Calcolo
A22: O | B22: Prime origini 2024: Albania ≈ 32.000 · Marocco ≈ 28.000 · Argentina 13.559 · India 12.258 · Brasile 11.058 | I22: ISTAT
A24: Fonti: Eurostat LFS 2025 · ISTAT Cittadini non comunitari 2024 · Cost. artt. 3, 10, 22; L. 91/1992; CEDU Prot. 4
A25: Verde = valore collegato al tab Funnel Italia. n.d. = nessuna fonte pubblica.

Sheet Fase 4
A1: Fase 4 · Cittadini UE (Romania) e protezione temporanea
A2: Dipende dal diritto dell’Unione, non dalla legge italiana.
A4: Codice | B4: Voce | D4: Persone | E4: Fase | F4: Stato giuridico oggi | G4: Cosa si può fare oggi | H4: Cambio di legge per remigrare | I4: Fonte
A5: TOT | B5: Fase 4 | C5: = | D5: =D6+D10 -> 1213642 | E5: Fase 4 | I5: Funnel Italia
A6: A | B6: Romania | C6: = | D6: ='Funnel Italia'!D20 -> 1053042 | E6: Fase 4 | F6: Libera circolazione (TFUE art. 21; dir. 2004/38) | G6: Allontanamento solo individuale: ordine pubblico (art. 20 D.Lgs. 30/2007) o senza risorse dopo 3 mesi (art. 21) | H6: Impossibile senza modificare i trattati / la dir. 2004/38 (unanimità); vietate le espulsioni collettive (CEDU Prot. 4 art. 4) | I6: ISTAT · 1.1.2025
A7: A1 | B7: di cui con lavoro o risorse | C7: + | D7: n.d. | E7: FUORI | F7: Diritto di soggiorno | G7: Nulla | H7: Trattati UE
A8: A2 | B8: di cui senza risorse dopo 3 mesi | C8: + | D8: n.d. | E8: Fase 4 | F8: Allontanabili (art. 21) | G8: Allontanamento, senza divieto di reingresso | H8: Nessuno | I8: Non misurato
A9: A3 | B9: di cui detenuti (≈ 11% dei detenuti stranieri) | C9: + | D9: n.d. | E9: Fase 1 | F9: Allontanabili (art. 20) | G9: Allontanamento + divieto reingresso 5-10 anni; esecuzione pena in Romania (DQ 2008/909) | H9: Nessuno | I9: Min. Giustizia: UE 2.819 detenuti in totale
A10: B | B10: Protezione temporanea (Ucraina) | C10: = | D10: ='Funnel Italia'!D27 -> 160600 | E10: Fase 4 | F10: Dir. 2001/55; scade 4.3.2028 | G10: Rientro volontario assistito; dal 2028 conversione in permesso ordinario (→ Fase 2) o rimpatrio | H10: Nessuno: decide il Consiglio UE | I10: ISTAT · 31.12.2024 (Eurostat 2026: 60.485)
A11: B1 | B11: di cui con lavoro (convertibili in Fase 2) | C11: + | D11: n.d. | E11: Fase 2 | I11: Non pubblicato
A12: B2 | B12: di cui senza lavoro | C12: + | D12: n.d. | E12: Fase 4 | G12: Rientro volontario con incentivo | H12: Nessuno | I12: Non pubblicato
A14: Fonti: Eurostat migr_pop1ctz · ISTAT · D.Lgs. 30/2007 artt. 20-21; Direttiva 2001/55; Decisione (UE) 2026/1912; DQ 2008/909/GAI
A15: Verde = valore collegato al tab Funnel Italia. n.d. = nessuna fonte pubblica.

Sheet FUORI
A1: FUORI · Nessuna remigrazione
A2: Riportato per completezza: queste righe chiudono la somma del Funnel.
A4: Codice | B4: Voce | D4: Persone | E4: Fase | F4: Stato giuridico oggi | G4: Cosa si può fare oggi | H4: Cambio di legge per remigrare | I4: Fonte
A5: TOT | B5: Fuori perimetro | C5: = | D5: =D6+D7+D8 -> 50647041 | E5: FUORI | I5: Funnel Italia
A6: A | B6: Italiani nati in Italia da genitori nati in Italia | C6: + | D6: ='Funnel Italia'!D14 -> 50057465 | E6: FUORI | F6: Cittadini | I6: Calcolo
A7: B | B7: Italiani dalla nascita nati all’estero (figli di emigrati, iure sanguinis) | C7: + | D7: ='Funnel Italia'!D18 -> 268748 | E7: FUORI | F7: Cittadini | I7: Calcolo
A8: C | B8: Cittadini di altri Stati UE (esclusa Romania) | C8: + | D8: ='Funnel Italia'!D21 -> 320828 | E8: FUORI | F8: Libera circolazione | G8: Allontanamento individuale per ordine pubblico (art. 20): vedi Fase 1 per i detenuti | H8: Trattati UE | I8: Calcolo
A10: Fonti: Funnel Italia
A11: Verde = valore collegato al tab Funnel Italia. n.d. = nessuna fonte pubblica.

Sheet Tracker 2027-2032
A1: Progress tracker 2027-2032 · tutte le categorie
A2: Ipotesi di base: entro pochi anni le norme UE vengono cambiate in senso favorevole all’esecuzione del GRP. Blu = obiettivi modificabili; nero = formule; verde = collegato al Funnel; testo = tappa.
A4: Fase | B4: Categoria | C4: Indicatore | D4: Base 2025 | E4: 2027 | F4: 2028 | G4: 2029 | H4: 2030 | I4: 2031 | J4: 2032 | K4: Cambio di legge richiesto
A6: Fase 1 · Irregolari e condannati (legge attuale)
A7: Fase 1 | B7: Irregolari | C7: Tasso di esecuzione degli ordini | D7: 0.224 | E7: 0.4 | F7: 0.55 | G7: 0.7 | H7: 0.85 | I7: 0.95 | J7: 1 | K7: Nessuno
A8: Fase 1 | B8: Irregolari | C8: Ordini di lasciare il territorio (ogni irregolare trovato riceve un ordine) | D8: ='Funnel Italia'!D39 -> 21295 | E8: 35000 | F8: 50000 | G8: 80000 | H8: 100000 | I8: 100000 | J8: 100000 | K8: Nessuno
A9: Fase 1 | B9: Irregolari | C9: Rimpatri eseguiti | D9: ='Funnel Italia'!D40 -> 4780 | E9: =ROUND(E8*E7,0) -> 14000 | F9: =ROUND(F8*F7,0) -> 27500 | G9: =ROUND(G8*G7,0) -> 56000 | H9: =ROUND(H8*H7,0) -> 85000 | I9: =ROUND(I8*I7,0) -> 95000 | J9: =ROUND(J8*J7,0) -> 100000 | K9: Nessuno
A10: Fase 1 | B10: Irregolari | C10: Quota volontari sui rimpatri | D10: 0.15 | E10: 0.2 | F10: 0.3 | G10: 0.4 | H10: 0.5 | I10: 0.5 | J10: 0.5 | K10: Nessuno
A11: Fase 1 | B11: Irregolari | C11: di cui volontari (RVA) | D11: ='Funnel Italia'!D43 -> 717 | E11: =ROUND(E9*E10,0) -> 2800 | F11: =ROUND(F9*F10,0) -> 8250 | G11: =ROUND(G9*G10,0) -> 22400 | H11: =ROUND(H9*H10,0) -> 42500 | I11: =ROUND(I9*I10,0) -> 47500 | J11: =ROUND(J9*J10,0) -> 50000 | K11: Nessuno: fondi e convenzione OIM
A12: Fase 1 | B12: Irregolari | C12: di cui forzati | D12: =D9-D11 -> 4063 | E12: =E9-E11 -> 11200 | F12: =F9-F11 -> 19250 | G12: =G9-G11 -> 33600 | H12: =H9-H11 -> 42500 | I12: =I9-I11 -> 47500 | J12: =J9-J11 -> 50000 | K12: Nessuno
A13: Fase 1 | B13: Irregolari | C13: Quota forzati che passa dal CPR | D13: 0.43 | E13: 0.4 | F13: 0.35 | G13: 0.33 | H13: 0.33 | I13: 0.33 | J13: 0.33 | K13: Nessuno
A14: Fase 1 | B14: Irregolari | C14: Giorni medi in CPR per rimpatrio | D14: 148 | E14: 120 | F14: 90 | G14: 75 | H14: 60 | I14: 60 | J14: 60 | K14: Nessuno: identificazione prima del trattenimento
A15: Fase 1 | B15: Irregolari | C15: Posti CPR necessari (occupazione 85%) | D15: =ROUND(D12*D13*D14/365/0.85,0) -> 833 | E15: =ROUND(E12*E13*E14/365/0.85,0) -> 1733 | F15: =ROUND(F12*F13*F14/365/0.85,0) -> 1954 | G15: =ROUND(G12*G13*G14/365/0.85,0) -> 2680 | H15: =ROUND(H12*H13*H14/365/0.85,0) -> 2712 | I15: =ROUND(I12*I13*I14/365/0.85,0) -> 3031 | J15: =ROUND(J12*J13*J14/365/0.85,0) -> 3191 | K15: Nessuno
A16: Fase 1 | B16: Irregolari | C16: Paesi con riammissione operativa (oggi: Albania, Georgia, Tunisia, Egitto) | D16: 4 | E16: + Marocco, Bangladesh | F16: + Pakistan, Nigeria | G16: + Algeria | H16: 8 | I16: 8 | J16: 8 | K16: Nessuno: leva visti (Codice visti art. 25a), commercio, aiuti
A17: Fase 1 | B17: Irregolari | C17: Stock di irregolari a fine anno (stima: 339k + 50k nuovi l’anno - rimpatri) | D17: 339000 | E17: =339000+50000-E9 -> 375000 | F17: =E17+50000-F9 -> 397500 | G17: =F17+50000-G9 -> 391500 | H17: =G17+50000-H9 -> 356500 | I17: =H17+50000-I9 -> 311500 | J17: =I17+50000-J9 -> 261500 | K17: Nessuno
A18: Fase 1 | B18: Irregolari | C18: Tempo rilevamento → decisione (giorni) | D18: n.d. | E18: 7 | F18: 1 | G18: 1 | H18: 1 | I18: 1 | J18: 1 | K18: Nessuno: fascicolo digitale unico
A19: Fase 1 | B19: Condannati | C19: Detenuti extra-UE identificati con lasciapassare richiesto entro 6 mesi | D19: n.d. | E19: 0.5 | F19: 1 | G19: 1 | H19: 1 | I19: 1 | J19: 1 | K19: Nessuno: protocollo DAP-Questure
A20: Fase 1 | B20: Condannati | C20: Espulsioni ex artt. 15-16 TU eseguite al fine pena o in alternativa alla pena | D20: 825 | E20: 2000 | F20: 4000 | G20: 6000 | H20: 7000 | I20: 8000 | J20: 8000 | K20: Nessuno (ultimo dato pubblico: 2018)
A21: Fase 1 | B21: Condannati | C21: Detenuti UE trasferiti a scontare la pena in patria (DQ 2008/909) | D21: n.d. | E21: 500 | F21: 1000 | G21: 1500 | H21: 2000 | I21: 2000 | J21: 2000 | K21: Nessuno: accordo operativo con Bucarest
A23: Fase 2 · Regolari extra-UE (legge ordinaria e accordi)
A24: Fase 2 | B24: Richiedenti asilo | C24: Quota domande da paesi < 20% in procedura di frontiera | D24: n.d. | E24: 1 | F24: 1 | G24: 1 | H24: 1 | I24: 1 | J24: 1 | K24: Nessuno: Patto UE in vigore dal 12.6.2026
A25: Fase 2 | B25: Richiedenti asilo | C25: Giorni tra diniego definitivo e ordine di rimpatrio | D25: n.d. | E25: 0 | F25: 0 | G25: 0 | H25: 0 | I25: 0 | J25: 0 | K25: Nessuno: atto unico (reg. rimpatri)
A26: Fase 2 | B26: Richiedenti asilo | C26: Quota dinieghi definitivi che producono un rimpatrio eseguito | D26: 0.1 | E26: 0.3 | F26: 0.6 | G26: 0.8 | H26: 1 | I26: 1 | J26: 1 | K26: Nessuno
A27: Fase 2 | B27: Lungo soggiornanti | C27: Condannati per reati artt. 380-381 c.p.p. revocati ed espulsi | D27: n.d. | E27: 1 | F27: 1 | G27: 1 | H27: 1 | I27: 1 | J27: 1 | K27: Nessuno (art. 9 c. 4 e 10 TU già in vigore)
A28: Fase 2 | B28: Lungo soggiornanti | C28: Controllo annuale assenze > 12 mesi via EES/SIS | D28: no | E28: 100% | F28: 100% | G28: 100% | H28: 100% | I28: 100% | J28: 100% | K28: Nessuno: procedura
A29: Fase 2 | B29: Lungo soggiornanti | C29: Revoche di status l’anno (condanne, assenze, frode) | D29: n.d. | E29: 2000 | F29: 4000 | G29: 5000 | H29: 5000 | I29: 5000 | J29: 5000 | K29: Nessuno
A30: Fase 2 | B30: Permessi a termine | C30: Mancati rinnovi tracciati per motivo e nazionalità | D30: no | E30: 100% | F30: 100% | G30: 100% | H30: 100% | I30: 100% | J30: 100% | K30: Nessuno: statistica Viminale
A31: Fase 2 | B31: Permessi a termine | C31: Attesa occupazione dopo perdita del lavoro (mesi) | D31: 12 | E31: 6 | F31: 3 | G31: 3 | H31: 3 | I31: 3 | J31: 3 | K31: Legge ordinaria: TU art. 22 c. 11 (2027)
A32: Fase 2 | B32: Permessi a termine | C32: Stagionali verificati in uscita (EES) | D32: n.d. | E32: 1 | F32: 1 | G32: 1 | H32: 1 | I32: 1 | J32: 1 | K32: Nessuno
A33: Fase 2 | B33: Permessi a termine | C33: Quota permessi scaduti non rinnovati che diventano ordine | D33: n.d. | E33: 0.5 | F33: 0.8 | G33: 1 | H33: 1 | I33: 1 | J33: 1 | K33: Nessuno
A34: Fase 2 | B34: Protezione sussidiaria e speciale | C34: Riesame sistematico alla scadenza (cessazione art. 15; non rinnovo art. 19) | D34: n.d. | E34: 1 | F34: 1 | G34: 1 | H34: 1 | I34: 1 | J34: 1 | K34: Nessuno; restringere art. 19 c. 1.1: legge ordinaria
A35: Fase 2 | B35: Rifugiati | C35: Revoca dello status per reati gravi e cessazione per paesi tornati sicuri | D35: n.d. | E35: 500 | F35: 1000 | G35: 2000 | H35: 3000 | I35: 3000 | J35: 3000 | K35: Revisione a livello UE della direttiva qualifiche (2003/109 e 2011/95)
A36: Fase 2 | B36: Stranieri nati in Italia | C36: Elezione automatica di cittadinanza a 18 anni | D36: sì | E36: abrogata | F36: no | G36: no | H36: no | I36: no | J36: no | K36: Legge ordinaria: art. 4 c. 2 L. 91/92
A38: Fase 3 · Cittadini di origine straniera (riforma costituzionale)
A39: Fase 3 | B39: Naturalizzati | C39: Acquisizioni di cittadinanza l’anno | D39: 217448 | E39: 120000 | F39: 60000 | G39: 40000 | H39: 30000 | I39: 30000 | J39: 30000 | K39: Legge ordinaria: L. 91/92 artt. 5, 9, 14 (requisiti, anni, lingua, reati)
A40: Fase 3 | B40: Naturalizzati | C40: Revoca per reati gravi entro 10 anni dall’acquisizione | D40: no | E40: legge approvata | F40: in vigore | G40: in vigore | H40: in vigore | I40: in vigore | J40: in vigore | K40: Legge ordinaria + probabile vaglio Corte cost. (art. 3)
A41: Fase 3 | B41: Naturalizzati | C41: Revoche di cittadinanza l’anno (oggi art. 10-bis: solo terrorismo) | D41: n.d. | E41: 100 | F41: 1000 | G41: 2000 | H41: 3000 | I41: 3000 | J41: 3000 | K41: Dipende dalla riga sopra
A42: Fase 3 | B42: Seconda generazione | C42: Riforma costituzionale artt. 3 e 22 (cittadini di origine straniera allontanabili) | D42: no | E42: 1ª lettura | F42: 2ª lettura | G42: referendum | H42: in vigore | I42: in vigore | J42: in vigore | K42: Riforma costituzionale (Cost. art. 138); revisione Prot. 4 CEDU con gli alleati
A43: Fase 3 | B43: Seconda generazione | C43: Rimpatri di cittadini di origine straniera condannati per reati gravi | D43: 0 | E43: 0 | F43: 0 | G43: 0 | H43: 500 | I43: 2000 | J43: 3000 | K43: Dopo la riforma: solo condannati, poi estensione
A44: Fase 3 | B44: Seconda generazione | C44: Rientri volontari incentivati (programma di remigrazione volontaria) | D44: n.d. | E44: 1000 | F44: 3000 | G44: 5000 | H44: 8000 | I44: 10000 | J44: 10000 | K44: Nessuno: programma con incentivo e rinuncia alla cittadinanza (art. 14 L. 91/92)
...

Sheet Esecuzione
A1: Esecuzione · modalità e fattibilità
A2: Come si effettua la remigrazione, caso per caso. Fattibilità: Alta / Media / Bassa / Nulla, con il motivo.
A4: 1 · Le sette modalità di remigrazione
A5: Modalità | B5: A chi si applica | C5: Passaggi operativi | D5: Attori | E5: Costo unitario | F5: Tempo medio | G5: Capacità oggi → 2032 | H5: Fattibilità
A6: 1. Rimpatrio volontario assistito (RVA) | B6: Fase 1 con ordine; Fase 2 dopo diniego o mancato rinnovo; Fase 4 Ucraina | C6: Colloquio in questura o CAS → adesione entro 7 gg → documento di viaggio → volo di linea → incentivo erogato nel paese d’origine in 2 tranche | D6: Questura, OIM, Frontex (biglietti), paese d’origine | E6: 560 € trasporto + 630-2.450 € incentivo UE + ≈ 400 € gestione | F6: 30-60 giorni | G6: ≈ 300 l’anno → 6.400 | H6: Alta
A7: 2. Accompagnamento su volo di linea | B7: Fase 1 identificati con documento; condannati a fine pena | C7: Ordine con accompagnamento → 2 agenti di scorta → consegna alle autorità del paese | D7: Questura, Polizia di frontiera, Frontex | E7: ≈ 3.400 € | F7: 7-30 giorni | G7: ≈ 3.000 l’anno → 4.000 | H7: Alta
A8: 3. Charter nazionale | B8: Fase 1 verso Tunisia, Egitto, Albania, Georgia, Nigeria | C8: Lista passeggeri concordata con il consolato → convalida → volo da Palermo, Roma, Milano | D8: Viminale, consolati, vettore | E8: ≈ 2.600 € a persona (media Frontex) | F8: Settimanale | G8: Tunisia 28 charter (2025), tetto 80/settimana → 100 charter l’anno | H8: Media
A9: 4. Charter Frontex congiunto | B9: Fase 1 verso paesi con pochi casi per Stato | C9: Adesione a volo organizzato da altro Stato → scorta Frontex | D9: Frontex, Questure | E9: ≈ 2.600 €, cofinanziato UE | F9: Mensile | G9: Centinaia l’anno → 1.500 | H9: Alta
A10: 5. Trattenimento in CPR o Gjadër → rimpatrio | B10: Fase 1 senza documenti o a rischio fuga | C10: Convalida giudice di pace entro 48 h → identificazione consolare → lasciapassare → volo | D10: Questura, giudice di pace, consolati, ente gestore | E10: 110 €/giorno × giorni + trasporto (oggi 16.560 € a 148 gg) | F10: 148 giorni → 60 | G10: 1.732 l’anno → ≈ 2.100 (1 forzato su 3) | H10: Media
A11: 6. Trasferimento dell’esecuzione della pena | B11: Condannati UE (Romania) ed extra-UE con accordo (Albania, Marocco, Tunisia) | C11: Istanza del PM o del detenuto → consenso dello Stato → traduzione | D11: Ministero Giustizia, DAP, Stato ricevente | E11: Risparmio: ≈ 140 €/giorno di carcere (ipotesi) | F11: 6-12 mesi | G11: Decine l’anno → 900 (UE) + 300 (extra-UE) | H11: Media
A12: 7. Allontanamento di cittadino UE | B12: Fase 4 Romania e altri UE, solo condannati o senza risorse | C12: Decreto del prefetto → ricorso TAR → esecuzione con accompagnamento → divieto reingresso SIS | D12: Prefettura, TAR, Polizia | E12: ≈ 1.000 € (volo breve, nessun documento da ottenere) | F12: 30-90 giorni | G12: n.d. → 1.000 | H12: Media
A14: 2 · Catena operativa Fase 1: dal rilevamento al rimpatrio
A15: Passaggio | B15: Cosa succede oggi | C15: Cosa cambia con il GRP | D15: Attore | E15: Indicatore | F15: Obiettivo 2032 | G15: Collo di bottiglia | H15: Fattibilità
A16: 1. Rilevamento | B16: 82.505 trovati; 1 ordine ogni 3,9 rilevamenti; molti “invitati” senza fascicolo | C16: Fascicolo digitale unico per persona (Eurodac + SIS + EES) aperto entro 24 h | D16: Polizie, Questure | E16: Quota rilevamenti con fascicolo entro 24 h | F16: 100% | G16: Sistemi non integrati tra Questure | H16: Alta
A17: 2. Decisione | B17: Ordine del prefetto; diniego asilo e ordine in atti separati | C17: Atto unico diniego + ordine (reg. UE rimpatri); ordine europeo valido in tutta l’UE | D17: Prefetto, Commissioni territoriali | E17: Giorni diniego → ordine | F17: 0 | G17: Contenzioso: ricorso con sospensiva | H17: Alta
A18: 3. Offerta volontaria | B18: Quasi assente (717 RVA in 31 mesi) | C18: Colloquio obbligatorio entro 7 gg; incentivo UE; partner OIM; informazione nei CAS | D18: Questura, OIM | E18: Quota ordini con offerta entro 7 gg | F18: 100% | G18: Fondi e personale | H18: Alta
A19: 4. Identificazione e documenti | B19: Collo di bottiglia: Marocco, Algeria, Pakistan, Bangladesh non rispondono; 148 gg in CPR | C19: Identificazione in carcere e in CAS prima dell’ordine; accordi con lasciapassare in 15 gg; leva visti art. 25a | D19: Questura, consolati, Farnesina | E19: Giorni richiesta → lasciapassare | F19: 15 | G19: Volontà politica dei paesi d’origine | H19: Media
A20: 5. Prevenzione della fuga | B20: CPR: 883 posti utilizzabili su 1.492; occupazione 46% | C20: Obbligo di firma e residenza; braccialetto; CPR solo per chi ha il documento in arrivo | D20: Questura, giudice di pace | E20: Giorni medi in CPR | F20: 60 | G20: Convalide e proroghe lente | H20: Media
A21: 6. Ricorsi | B21: Sospensiva frequente; tempi 6-12 mesi | C21: Rito accelerato 30 gg per paesi sicuri; udienza in videoconferenza | D21: Tribunali | E21: Giorni medi del ricorso | F21: 30 | G21: Carico dei tribunali | H21: Media
A22: 7. Trasferimento | B22: Charter limitati dai tetti (Tunisia 80/settimana); volo di linea costoso | C22: Programmazione annuale dei voli con Frontex; charter congiunti | D22: Viminale, Frontex | E22: Rimpatri eseguiti | F22: 12.777 | G22: Capacità di accoglienza dei paesi d’origine | H22: Media
A23: 8. Reinserimento | B23: Nessun monitoraggio | C23: Incentivo in 2 tranche; verifica a 6 mesi; dato pubblicato | D23: OIM, paese d’origine | E23: Quota rientrati verificati a 6 mesi | F23: 80% | G23: Nessuno | H23: Alta
A25: 3 · Fase 2, 3, 4: come si attiva il perimetro
A26: Categoria | B26: Evento che apre il perimetro | C26: Procedura concreta | D26: Attore | E26: Persone l’anno (ordine di grandezza) | F26: Tempo | G26: Vincolo principale | H26: Fattibilità
A27: Richiedenti asilo (Fase 2) | B27: Diniego in prima istanza (≈ 50.400 l’anno) | C27: Procedura di frontiera 12 settimane nei CTRA per paesi < 20%; diniego + ordine in un atto; RVA offerto nel centro | D27: Commissioni, Questura, CTRA | E27: 50.000 | F27: 12 settimane | G27: Ricorsi; posti CTRA (1.033) | H27: Alta
A28: Permessi a termine (Fase 2) | B28: Perdita del lavoro oltre 12 mesi; reddito sotto soglia; fine stagione o corso | C28: Incrocio INPS-Questura al rinnovo; stagionali: controllo uscita EES; mancato rinnovo → ordine | D28: Questura, INPS, EES | E28: n.d. (da misurare) | F28: Alla scadenza | G28: Nessun dato oggi; art. 8 CEDU per famiglie | H28: Media
A29: Lungo soggiornanti (Fase 2) | B29: Condanna per reati artt. 380-381 c.p.p.; assenza > 12 mesi | C29: Segnalazione automatica DAP → Questura; revoca; espulsione a fine pena | D29: DAP, Questura, Prefetto | E29: Centinaia | F29: Durante la pena | G29: Valutazione individuale; ricorsi | H29: Media
A30: Protezione sussidiaria e speciale (Fase 2) | B30: Scadenza del permesso (5 e 2 anni) | C30: Riesame d’ufficio sulla situazione del paese; cessazione → ordine | D30: Commissione nazionale | E30: Migliaia (es. Siria, Ucraina) | F30: Alla scadenza | G30: Non-refoulement | H30: Media
A31: Condannati extra-UE (Fase 1) | B31: Sentenza definitiva | C31: Identificazione consolare in carcere nei primi 6 mesi; lasciapassare pronto; espulsione al fine pena o alternativa (residuo ≤ 2 anni) | D31: DAP, Questura, magistrato di sorveglianza | E31: 4.000 nel 2032 | F31: Entro la pena | G31: Riammissione dei paesi | H31: Media
A32: Romania (Fase 4) | B32: Condanna o assenza di risorse | C32: Allontanamento art. 20-21; esecuzione pena in Romania (DQ 2008/909) | D32: Prefetto, Min. Giustizia | E32: 1.000 + 900 | F32: 3-12 mesi | G32: Dir. 2004/38: solo casi individuali | H32: Media
A33: Protezione temporanea (Fase 4) | B33: Scadenza 4.3.2028 | C33: Censimento 2027: lavoro sì/no; conversione per chi lavora; RVA verso Ucraina per gli altri | D33: Viminale, OIM, Ucraina | E33: 160.000 in 2 anni | F33: 2027-2029 | G33: Situazione di guerra | H33: Media
A34: Naturalizzati (Fase 3) | B34: Legge sulla revoca (2027) e riforma costituzionale (2027-2030) | C34: 2027 legge ordinaria: revoca per reati gravi entro 10 anni; 2027-29 riforma artt. 3 e 22 con referendum; dal 2030 allontanamento dei condannati; programma di rientro volontario con incentivo dal 2027 | D34: Parlamento, elettori, Viminale | E34: 3.000 revoche + 10.000 rientri volontari l’anno a regime | F34: 3 anni | G34: Tempi parlamentari; apolidia (serve seconda cittadinanza) | H34: Media
A35: Seconda generazione (Fase 3) | B35: Idem; nel frattempo chiusura del rubinetto: art. 4 c. 2 e art. 14 L. 91/92 | C35: Idem; rinuncia alla cittadinanza incentivata (art. 14) per chi aderisce al rientro volontario | D35: Parlamento, Viminale | E35: Idem | F35: 3 anni | G35: Idem | H35: Media
A37: 4 · Paesi d’origine: riammissione
A38: Paese | B38: Situazione 2025 | C38: Cosa serve | D38: Leva | E38: Rimpatri IT 2025 | F38: Obiettivo 2032 | G38: Strumento | H38: Fattibilità
A39: Tunisia | B39: Accordo operativo; tetto 80/settimana; charter 78 → 28; 1.849 → 600 rimpatri | C39: Alzare il tetto a 200/settimana; charter programmati | D39: MoU UE-Tunisia 2023 (105 M€); quote lavoro | E39: 600 | F39: 3.000 | G39: Charter nazionale | H39: Media
A40: Egitto | B40: 18 charter; 454 rimpatri; 52% degli ingressi in CPR rimpatriati | C40: Raddoppiare i charter | D40: Partenariato UE-Egitto 2024 (7,4 mld €); visti | E40: 454 | F40: 1.500 | G40: Charter nazionale | H40: Media
A41: Albania | B41: Riammissione funziona; accordo esecuzione pena 2002 | C41: Volume | D41: Candidatura UE | E41: n.d. | F41: 1.000 | G41: Volo di linea; trasferimento pena | H41: Alta
A42: Marocco | B42: Prima nazionalità in carcere (4.358); lasciapassare rari | C42: Accordo di riammissione con tempi certi | D42: Visti art. 25a; commercio UE; Piano Mattei | E42: n.d. | F42: 1.500 | G42: Accordo bilaterale | H42: Bassa
A43: Bangladesh | B43: Primo paese per richieste d’asilo (32.865); rigetti alti; riammissione lenta | C43: Accordo UE-Bangladesh (SOP 2017) applicato | D43: Visti; quote lavoro (decreto flussi) | E43: n.d. | F43: 1.500 | G43: Charter Frontex | H43: Media
A44: Pakistan | B44: Riammissione formale (accordo UE 2010) ma identificazione lenta | C44: Identificazione consolare in carcere e CAS | D44: Visti; GSP+ commercio | E44: n.d. | F44: 800 | G44: Charter Frontex | H44: Bassa
...

Sheet Funnel 27 paesi
A1: Great Remigration Plan · Funnel per i 27 Stati membri
A2: Stesse categorie e stesse fasi del tab Italia. Fonti solo Eurostat (1.1.2025; LFS 2025; flussi 2025). n.d. = non pubblicato da Eurostat.
A4: Codice | B4: Categoria | D4: Fase | E4: Italia | F4: Austria | G4: Belgio | H4: Bulgaria | I4: Cipro | J4: Croazia | K4: Danimarca | L4: Estonia | M4: Finlandia | N4: Francia | O4: Germania | P4: Grecia | Q4: Irlanda | R4: Lettonia | S4: Lituania | T4: Lussemburgo | U4: Malta | V4: Paesi Bassi | W4: Polonia | X4: Portogallo | Y4: Repubblica Ceca | Z4: Romania | AA4: Slovacchia | AB4: Slovenia | AC4: Spagna | AD4: Svezia | AE4: Ungheria | AF4: UE27 (somma dei paesi con dato)
B5: Popolazione residente | C5: = | E5: 58943464 | F5: 9197213 | G5: 11883495 | H5: 6437360 | I5: 982966 | J5: 3874350 | K5: 5992734 | L5: 1369995 | M5: 5635971 | N5: 68882600 | O5: 83577140 | P5: 10372335 | Q5: 5440278 | R5: 1860565 | S5: 2890664 | T5: 681973 | U5: 574250 | V5: 18044027 | W5: 36497495 | X5: 10749635 | Y5: 10909500 | Z5: 19043151 | AA5: 5419451 | AB5: 2130850 | AC5: 49128297 | AD5: 10587710 | AE5: 9539502 | AF5: =SUM(E5:AE5) -> 450646971
A6: A | B6: Cittadini | C6: = | E6: 53572213 | F6: 7341794 | G6: 10193392 | H6: 6284422 | I6: 739677 | J6: 3720379 | K6: 5315187 | L6: 1123385 | M6: 5224870 | N6: 62414394 | O6: 71184865 | P6: 9635274 | Q6: 4565956 | R6: 1630884 | S6: 2740912 | T6: 361247 | U6: 405312 | V6: 16428041 | W6: 36069586 | X6: n.d. | Y6: 9926844 | Z6: 18674247 | AA6: 5350766 | AB6: 1915919 | AC6: 42216326 | AD6: 9755897 | AE6: 9284059 | AF6: =SUM(E6:AE6) -> 396075848
A7: A1 | B7: nati nel paese | C7: = | E7: =E6-E10 -> 51213465 | F7: =F6-F10 -> 6831147 | G7: =G6-G10 -> 9243106 | H7: =H6-H10 -> 6177305 | I7: n.d. | J7: n.d. | K7: =K6-K10 -> 5060116 | L7: =L6-L10 -> 1057254 | M7: =M6-M10 -> 5028999 | N7: n.d. | O7: n.d. | P7: n.d. | Q7: n.d. | R7: =R6-R10 -> 1555619 | S7: n.d. | T7: =T6-T10 -> 291230 | U7: n.d. | V7: =V6-V10 -> 14904418 | W7: n.d. | X7: n.d. | Y7: n.d. | Z7: n.d. | AA7: =AA6-AA10 -> 5185351 | AB7: =AB6-AB10 -> 1785195 | AC7: =AC6-AC10 -> 39164944 | AD7: =AD6-AD10 -> 8314731 | AE7: =AE6-AE10 -> 8840023 | AF7: =SUM(E7:AE7) -> 164652903
A8: A1a | B8: da genitori nati nel paese (residuo) | C8: + | D8: FUORI | E8: =E7-E9 -> 50057565 | F8: =F7-F9 -> 6189047 | G8: =G7-G9 -> 8170506 | H8: =H7-H9 -> 6163805 | I8: n.d. | J8: n.d. | K8: n.d. | L8: =L7-L9 -> 933054 | M8: =M7-M9 -> 4893899 | N8: n.d. | O8: n.d. | P8: n.d. | Q8: n.d. | R8: =R7-R9 -> 1369119 | S8: n.d. | T8: =T7-T9 -> 215430 | U8: n.d. | V8: =V7-V9 -> 13228418 | W8: n.d. | X8: n.d. | Y8: n.d. | Z8: n.d. | AA8: =AA7-AA9 -> 5132651 | AB8: =AB7-AB9 -> 1635495 | AC8: =AC7-AC9 -> 37931444 | AD8: =AD7-AD9 -> 7482931 | AE8: =AE7-AE9 -> 8708423 | AF8: =SUM(E8:AE8) -> 152111787
A9: A1b | B9: seconda generazione, cittadini 15-74 (LFS) | C9: + | D9: Fase 3 | E9: 1155900 | F9: 642100 | G9: 1072600 | H9: 13500 | I9: 30000 | J9: 311700 | K9: n.d. | L9: 124200 | M9: 135100 | N9: 6550000 | O9: 8141700 | P9: 219200 | Q9: 293400 | R9: 186500 | S9: 56800 | T9: 75800 | U9: n.d. | V9: 1676000 | W9: 339800 | X9: 397600 | Y9: 268700 | Z9: 6700 | AA9: 52700 | AB9: 149700 | AC9: 1233500 | AD9: 831800 | AE9: 131600 | AF9: =SUM(E9:AE9) -> 24096600
A10: A2 | B10: nati all’estero | C10: = | E10: 2358748 | F10: 510647 | G10: 950286 | H10: 107117 | I10: n.d. | J10: n.d. | K10: 255071 | L10: 66131 | M10: 195871 | N10: n.d. | O10: n.d. | P10: n.d. | Q10: n.d. | R10: 75265 | S10: n.d. | T10: 70017 | U10: n.d. | V10: 1523623 | W10: n.d. | X10: n.d. | Y10: n.d. | Z10: n.d. | AA10: 165415 | AB10: 130724 | AC10: 3051382 | AD10: 1441166 | AE10: 444036 | AF10: =SUM(E10:AE10) -> 11345499
A11: A2a | B11: naturalizzati: acquisizioni 2015-2024 (stima per difetto) | C11: + | D11: Fase 3 | E11: 1663746 | F11: 100006 | G11: 410150 | H11: 10224 | I11: 28915 | J11: 11882 | K11: 66980 | L11: 9554 | M11: 96768 | N11: 1099169 | O11: 1483382 | P11: 189352 | Q11: 116986 | R11: 14003 | S11: 1810 | T11: 50743 | U11: 11077 | V11: 434596 | W11: 75238 | X11: 221070 | Y11: 40468 | Z11: 85080 | AA11: 5993 | AB11: 16378 | AC11: 1466064 | AD11: 699792 | AE11: 29707 | AF11: =SUM(E11:AE11) -> 8439133
A12: A2b | B12: altri nati all’estero (residuo) | C12: + | D12: FUORI | E12: =E10-E11 -> 695002 | F12: =F10-F11 -> 410641 | G12: =G10-G11 -> 540136 | H12: =H10-H11 -> 96893 | I12: n.d. | J12: n.d. | K12: =K10-K11 -> 188091 | L12: =L10-L11 -> 56577 | M12: =M10-M11 -> 99103 | N12: n.d. | O12: n.d. | P12: n.d. | Q12: n.d. | R12: =R10-R11 -> 61262 | S12: n.d. | T12: =T10-T11 -> 19274 | U12: n.d. | V12: =V10-V11 -> 1089027 | W12: n.d. | X12: n.d. | Y12: n.d. | Z12: n.d. | AA12: =AA10-AA11 -> 159422 | AB12: =AB10-AB11 -> 114346 | AC12: =AC10-AC11 -> 1585318 | AD12: =AD10-AD11 -> 741374 | AE12: =AE10-AE11 -> 414329 | AF12: =SUM(E12:AE12) -> 6270795
A13: B | B13: Cittadini di altri Stati UE | C13: + | D13: FUORI | E13: 1373870 | F13: 923854 | G13: 1006037 | H13: 31035 | I13: 99030 | J13: 23448 | K13: 276115 | L13: 22690 | M13: 107956 | N13: 1621028 | O13: 4350923 | P13: 114128 | Q13: 366693 | R13: 3937 | S13: 3662 | T13: 244291 | U13: 45771 | V13: 770888 | W13: 32317 | X13: n.d. | Y13: 197668 | Z13: 68774 | AA13: 39933 | AB13: 21433 | AC13: 1757955 | AD13: 306724 | AE13: 87962 | AF13: =SUM(E13:AE13) -> 13898122
A14: C | B14: Cittadini extra-UE residenti | C14: = | E14: 3996856 | F14: 909689 | G14: 662127 | H14: 115754 | I14: 144259 | J14: 129750 | K14: 392951 | L14: 223135 | M14: 300096 | N14: 4847178 | O14: 8024309 | P14: 622933 | Q14: 506707 | R14: 225629 | S14: 144294 | T14: 76142 | U14: 123167 | V14: 821732 | W14: 392169 | X14: n.d. | Y14: 784772 | Z14: 299603 | AA14: 25736 | AB14: 193498 | AC14: 5149235 | AD14: 508931 | AE14: 167205 | AF14: =SUM(E14:AE14) -> 29787857
A15: C1 | B15: protezione temporanea | C15: + | D15: Fase 4 | E15: 60485 | F15: 92455 | G15: 93425 | H15: 78105 | I15: 25465 | J15: 28540 | K15: 48685 | L15: 34395 | M15: 78225 | N15: 51885 | O15: 1251105 | P15: 38140 | Q15: 119375 | R15: 31250 | S15: 51540 | T15: 4060 | U15: 2495 | V15: 134090 | W15: 969250 | X15: 66740 | Y15: 393055 | Z15: 201890 | AA15: 139580 | AB15: 11280 | AC15: 255245 | AD15: 49615 | AE15: 43300 | AF15: =SUM(E15:AE15) -> 4353675
A16: C2 | B16: richiedenti asilo in attesa (dic 2025) | C16: + | D16: Fase 2 | E16: 234165 | F16: 22555 | G16: 58720 | H16: 1630 | I16: 23225 | J16: 505 | K16: 2475 | L16: 325 | M16: 4220 | N16: 153200 | O16: 306650 | P16: 31945 | Q16: 32620 | R16: 725 | S16: 160 | T16: 4195 | U16: 1415 | V16: 63295 | W16: 12780 | X16: 8595 | Y16: 625 | Z16: 295 | AA16: 90 | AB16: 1480 | AC16: 248760 | AD16: 6205 | AE16: 50 | AF16: =SUM(E16:AE16) -> 1220905
A17: C3 | B17: altri regolari: lungo soggiornanti e permessi a termine (residuo) | C17: + | D17: Fase 2 | E17: =E14-E15-E16 -> 3702206 | F17: =F14-F15-F16 -> 794679 | G17: =G14-G15-G16 -> 509982 | H17: =H14-H15-H16 -> 36019 | I17: =I14-I15-I16 -> 95569 | J17: =J14-J15-J16 -> 100705 | K17: =K14-K15-K16 -> 341791 | L17: =L14-L15-L16 -> 188415 | ... W17: =W14-W15-W16 -> -589861 | X17: n.d. | Y17: =Y14-Y15-Y16 -> 391092 | Z17: =Z14-Z15-Z16 -> 97418 | AA17: =AA14-AA15-AA16 -> -113934 | AB17: =AB14-AB15-AB16 -> 180738 | AC17: =AC14-AC15-AC16 -> 4645230 | AD17: =AD14-AD15-AD16 -> 453111 | AE17: =AE14-AE15-AE16 -> 123855 | AF17: =SUM(E17:AE17) -> 24288612
A18: D | B18: Irregolari presenti (stock) | C18: + | D18: Fase 1 | E18: 339000 | F18: n.d. | G18: n.d. | H18: n.d. | I18: n.d. | J18: n.d. | K18: n.d. | L18: n.d. | M18: n.d. | N18: n.d. | O18: n.d. | P18: n.d. | Q18: n.d. | R18: n.d. | S18: n.d. | T18: n.d. | U18: n.d. | V18: n.d. | W18: n.d. | X18: n.d. | Y18: n.d. | Z18: n.d. | AA18: n.d. | AB18: n.d. | AC18: n.d. | AD18: n.d. | AE18: n.d. | AF18: =SUM(E18:AE18) -> 339000
A20: Flussi 2025
A21: Codice | B21: Passaggio | D21: Fase | E21: Italia | F21: Austria | G21: Belgio | H21: Bulgaria | I21: Cipro | J21: Croazia | K21: Danimarca | L21: Estonia | M21: Finlandia | N21: Francia | O21: Germania | P21: Grecia | Q21: Irlanda | R21: Lettonia | S21: Lituania | T21: Lussemburgo | U21: Malta | V21: Paesi Bassi | W21: Polonia | X21: Portogallo | Y21: Repubblica Ceca | Z21: Romania | AA21: Slovacchia | AB21: Slovenia | AC21: Spagna | AD21: Svezia | AE21: Ungheria | AF21: UE27
A22: F1 | B22: Trovati in posizione irregolare | D22: Fase 1 | E22: 82505 | F22: 16550 | G22: 9420 | H22: 7745 | I22: 5335 | J22: 20300 | K22: 1375 | L22: 585 | M22: 660 | N22: 159460 | O22: 168360 | P22: 60800 | Q22: 5460 | R22: 2410 | S22: 5035 | T22: 2150 | U22: 2150 | V22: 3955 | W22: 17650 | X22: 735 | Y22: 10370 | Z22: 24350 | AA22: 1535 | AB22: 28575 | AC22: 58910 | AD22: 2495 | AE22: 20515 | AF22: =SUM(E22:AE22) -> 719390
A23: F2 | B23: Ordini di lasciare il territorio | D23: Fase 1 | E23: 21295 | F23: 11165 | G23: 25340 | H23: 3880 | I23: 15185 | J23: 11330 | K23: 2280 | L23: 660 | M23: 5070 | N23: 137550 | O23: 55240 | P23: 26635 | Q23: 6260 | R23: 2640 | S23: 4900 | T23: 1340 | U23: 1090 | V23: 31230 | W23: 14760 | X23: 18245 | Y23: 5250 | Z23: 2860 | AA23: 500 | AB23: 880 | AC23: 53700 | AD23: 18340 | AE23: 9080 | AF23: =SUM(E23:AE23) -> 486705
A24: F3 | B24: Rimpatri verso paesi terzi | D24: Fase 1 | E24: 4780 | F24: 7305 | G24: 4955 | H24: 1150 | I24: 10630 | J24: 6560 | K24: 975 | L24: 565 | M24: 1820 | N24: 14940 | O24: 29295 | P24: 5050 | Q24: 2030 | R24: 2280 | S24: 4545 | T24: 370 | U24: 1065 | V24: 4825 | W24: 9690 | X24: 825 | Y24: 3180 | Z24: 775 | AA24: 395 | AB24: 175 | AC24: 5705 | AD24: 11250 | AE24: 4135 | AF24: =SUM(E24:AE24) -> 139270
A25: F3/F2 | B25: Tasso di esecuzione | D25: Fase 1 | E25: =IF(ISNUMBER(E23),E24/E23,"n.d.") -> 0.22446584 | F25: =IF(ISNUMBER(F23),F24/F23,"n.d.") -> 0.65427676 | G25: =IF(ISNUMBER(G23),G24/G23,"n.d.") -> 0.19554065 | H25: =IF(ISNUMBER(H23),H24/H23,"n.d.") -> 0.29639175 | I25: =IF(ISNUMBER(I23),I24/I23,"n.d.") -> 0.70003293 | J25: =IF(ISNUMBER(J23),J24/J23,"n.d.") -> 0.57899382 | K25: =IF(ISNUMBER(K23),K24/K23,"n.d.") -> 0.42763158 | L25: =IF(ISNUMBER(L23),L24/L23,"n.d.") -> 0.85606061 | ... AF25: =IF(ISNUMBER(AF23),AF24/AF23,"n.d.") -> 0.28614869
A26: Memo | B26: Permessi di soggiorno validi (Eurostat migr_resvalid, 31.12.2024) | E26: 4257673 | F26: 596239 | G26: 535538 | H26: 135041 | I26: 200652 | J26: 135075 | K26: 396091 | L26: 187350 | M26: 274966 | N26: 4419080 | O26: 5935591 | P26: 713407 | Q26: 331623 | R26: 244320 | S26: 158277 | T26: 68865 | U26: 132067 | V26: 831413 | W26: 1055532 | X26: 1122061 | Y26: 486518 | Z26: 223782 | AA26: 161007 | AB26: 228390 | AC26: 4296727 | AD26: 429685 | AE26: 211288 | AF26: =SUM(E26:AE26) -> 27768258
A28: Differenze rispetto al tab Italia: A2a usa le acquisizioni cumulate 2015-2024 (Eurostat) al posto dello stock ISTAT; C3 non distingue lungo soggiornanti e permessi a termine (Eurostat migr_reslong da estrarre); B non isola la quota “tipo Romania” (Fase 4): serve migr_pop1ctz per cittadinanza; D (stock irregolari) esiste solo per l’Italia (ISMU).
A29: Danimarca e Malta: Eurostat non pubblica la LFS per cittadinanza (A1b n.d.). Portogallo: popolazione per cittadinanza non pubblicata (A, B, C n.d.). Germania, Francia, Polonia e altri 9: cittadini nati all’estero n.d. (A2 n.d.).

Sheet Costi
A1: Costi 2027-2032 · Italia
A2: Blu = ipotesi modificabili; nero = formule; verde = collegato al Tracker. Importi in euro; totali in milioni.
A4: 1 · Costi unitari (ipotesi)
A5: Voce | B5: Valore | I5: Fonte / nota
A6: Volontario: trasporto | B6: 560 | I6: Stima UE (biglietto aereo medio)
A7: Volontario: incentivo di reinserimento | B7: 1500 | I7: UE 630-2.450 € dal 1.6.2026; valore medio
A8: Volontario: gestione (OIM, colloqui) | B8: 400 | I8: Ipotesi
A9: Forzato: trasporto e scorta (volo di linea, 2 agenti) | B9: 3400 | I9: Stima UE bassa; Frontex media 2.600 €
A10: Forzato: charter a persona | B10: 2600 | I10: Frontex 2024: 146,2 M€ / 56.263 rimpatri
A11: CPR: costo per giorno tutto compreso (gestione + polizia + struttura) | B11: 110 | I11: ActionAid/UniBa: 16.560 € a 148 giorni ≈ 112 €/giorno; gestione sola 37-77 €
A12: CPR: capex per posto nuovo | B12: 21000 | I12: Porto Empedocle 1 M€ / 50 posti; Gjadër 153.000 €
A13: Procedura di frontiera: costo aggiuntivo per domanda rispetto all’accoglienza ordinaria | B13: 200 | I13: 40 giorni × (40 € CTRA − 35 € CAS); CTRA 37,22 €/giorno Porto Empedocle, 76,57 € Gjadër
A14: Accoglienza: costo per giorno a persona | B14: 35 | I14: CAS/SAI, dato standard
A15: Carcere: costo per giorno a detenuto | B15: 140 | I15: Ipotesi da verificare (Antigone ≈ 137 €)
A16: Allontanamento cittadino UE | B16: 1000 | I16: Ipotesi: volo breve, nessun documento
A17: Rientro volontario in Ucraina (trasporto + incentivo) | B17: 1000 | I17: Ipotesi
... A25: Giorni di carcere risparmiati per espulsione alternativa/trasferimento | B25: 365 | I25: Ipotesi: residuo pena medio 1 anno
A27: 2 · Volumi (dal Tracker)
A28: Voce | B28: 2027 | C28: 2028 | D28: 2029 | E28: 2030 | F28: 2031 | G28: 2032 | I28: Fonte
A29: Rimpatri volontari assistiti | B29: =IF(ISNUMBER('Tracker 2027-2032'!E11),'Tracker 2027-2032'!E11,0) -> 2800 | C29: =IF(ISNUMBER('Tracker 2027-2032'!F11),'Tracker 2027-2032'!F11,0) -> 8250 | D29: =IF(ISNUMBER('Tracker 2027-2032'!G11),'Tracker 2027-2032'!G11,0) -> 22400 | E29: =IF(ISNUMBER('Tracker 2027-2032'!H11),'Tracker 2027-2032'!H11,0) -> 42500 | F29: =IF(ISNUMBER('Tracker 2027-2032'!I11),'Tracker 2027-2032'!I11,0) -> 47500 | G29: =IF(ISNUMBER('Tracker 2027-2032'!J11),'Tracker 2027-2032'!J11,0) -> 50000 | I29: Tracker
A30: Rimpatri forzati | B30: =IF(ISNUMBER('Tracker 2027-2032'!E12),'Tracker 2027-2032'!E12,0) -> 11200 | C30: =IF(ISNUMBER('Tracker 2027-2032'!F12),'Tracker 2027-2032'!F12,0) -> 19250 | D30: =IF(ISNUMBER('Tracker 2027-2032'!G12),'Tracker 2027-2032'!G12,0) -> 33600 | E30: =IF(ISNUMBER('Tracker 2027-2032'!H12),'Tracker 2027-2032'!H12,0) -> 42500 | F30: =IF(ISNUMBER('Tracker 2027-2032'!I12),'Tracker 2027-2032'!I12,0) -> 47500 | G30: =IF(ISNUMBER('Tracker 2027-2032'!J12),'Tracker 2027-2032'!J12,0) -> 50000 | I30: Tracker
A31: Quota forzati dal CPR | B31: =IF(ISNUMBER('Tracker 2027-2032'!E13),'Tracker 2027-2032'!E13,0) -> 0.4 | C31: =IF(ISNUMBER('Tracker 2027-2032'!F13),'Tracker 2027-2032'!F13,0) -> 0.35 | D31: =IF(ISNUMBER('Tracker 2027-2032'!G13),'Tracker 2027-2032'!G13,0) -> 0.33 | E31: =IF(ISNUMBER('Tracker 2027-2032'!H13),'Tracker 2027-2032'!H13,0) -> 0.33 | F31: =IF(ISNUMBER('Tracker 2027-2032'!I13),'Tracker 2027-2032'!I13,0) -> 0.33 | G31: =IF(ISNUMBER('Tracker 2027-2032'!J13),'Tracker 2027-2032'!J13,0) -> 0.33 | I31: Tracker
A32: Giorni medi in CPR | B32: =IF(ISNUMBER('Tracker 2027-2032'!E14),'Tracker 2027-2032'!E14,0) -> 120 | C32: =IF(ISNUMBER('Tracker 2027-2032'!F14),'Tracker 2027-2032'!F14,0) -> 90 | D32: =IF(ISNUMBER('Tracker 2027-2032'!G14),'Tracker 2027-2032'!G14,0) -> 75 | E32: =IF(ISNUMBER('Tracker 2027-2032'!H14),'Tracker 2027-2032'!H14,0) -> 60 | F32: =IF(ISNUMBER('Tracker 2027-2032'!I14),'Tracker 2027-2032'!I14,0) -> 60 | G32: =IF(ISNUMBER('Tracker 2027-2032'!J14),'Tracker 2027-2032'!J14,0) -> 60 | I32: Tracker
A33: Posti CPR necessari | B33: =IF(ISNUMBER('Tracker 2027-2032'!E15),'Tracker 2027-2032'!E15,0) -> 1733 | C33: =IF(ISNUMBER('Tracker 2027-2032'!F15),'Tracker 2027-2032'!F15,0) -> 1954 | D33: =IF(ISNUMBER('Tracker 2027-2032'!G15),'Tracker 2027-2032'!G15,0) -> 2680 | E33: =IF(ISNUMBER('Tracker 2027-2032'!H15),'Tracker 2027-2032'!H15,0) -> 2712 | F33: =IF(ISNUMBER('Tracker 2027-2032'!I15),'Tracker 2027-2032'!I15,0) -> 3031 | G33: =IF(ISNUMBER('Tracker 2027-2032'!J15),'Tracker 2027-2032'!J15,0) -> 3191 | I33: Tracker
A34: Espulsioni di detenuti (artt. 15-16) | B34: =IF(ISNUMBER('Tracker 2027-2032'!E20),'Tracker 2027-2032'!E20,0) -> 2000 | C34: =IF(ISNUMBER('Tracker 2027-2032'!F20),'Tracker 2027-2032'!F20,0) -> 4000 | D34: =IF(ISNUMBER('Tracker 2027-2032'!G20),'Tracker 2027-2032'!G20,0) -> 6000 | E34: =IF(ISNUMBER('Tracker 2027-2032'!H20),'Tracker 2027-2032'!H20,0) -> 7000 | F34: =IF(ISNUMBER('Tracker 2027-2032'!I20),'Tracker 2027-2032'!I20,0) -> 8000 | G34: =IF(ISNUMBER('Tracker 2027-2032'!J20),'Tracker 2027-2032'!J20,0) -> 8000 | I34: Tracker
A35: Detenuti UE trasferiti (DQ 2008/909) | B35: =IF(ISNUMBER('Tracker 2027-2032'!E21),'Tracker 2027-2032'!E21,0) -> 500 | C35: =IF(ISNUMBER('Tracker 2027-2032'!F21),'Tracker 2027-2032'!F21,0) -> 1000 | D35: =IF(ISNUMBER('Tracker 2027-2032'!G21),'Tracker 2027-2032'!G21,0) -> 1500 | E35: =IF(ISNUMBER('Tracker 2027-2032'!H21),'Tracker 2027-2032'!H21,0) -> 2000 | F35: =IF(ISNUMBER('Tracker 2027-2032'!I21),'Tracker 2027-2032'!I21,0) -> 2000 | G35: =IF(ISNUMBER('Tracker 2027-2032'!J21),'Tracker 2027-2032'!J21,0) -> 2000 | I35: Tracker
A36: Domande in procedura di frontiera (paesi < 20%) | B36: =IF(ISNUMBER('Tracker 2027-2032'!E24),'Tracker 2027-2032'!E24*60000,0) -> 60000 | C36: =IF(ISNUMBER('Tracker 2027-2032'!F24),'Tracker 2027-2032'!F24*60000,0) -> 60000 | D36: =IF(ISNUMBER('Tracker 2027-2032'!G24),'Tracker 2027-2032'!G24*60000,0) -> 60000 | E36: =IF(ISNUMBER('Tracker 2027-2032'!H24),'Tracker 2027-2032'!H24*60000,0) -> 60000 | F36: =IF(ISNUMBER('Tracker 2027-2032'!I24),'Tracker 2027-2032'!I24*60000,0) -> 60000 | G36: =IF(ISNUMBER('Tracker 2027-2032'!J24),'Tracker 2027-2032'!J24*60000,0) -> 60000 | I36: Quota Tracker × ≈ 60.000 domande da paesi < 20% (ipotesi)
